[27/Jan/2020 18:25:43] ERROR [django.request:228] Internal Server Error: /challenge/3897375565719780/
Traceback (most recent call last):
  File "/root/.virtualenvs/venv/lib/python3.6/site-packages/django/core/handlers/exception.py", line 34, in inner
    response = get_response(request)
  File "/root/.virtualenvs/venv/lib/python3.6/site-packages/django/core/handlers/base.py", line 115, in _get_response
    response = self.process_exception_by_middleware(e, request)
  File "/root/.virtualenvs/venv/lib/python3.6/site-packages/django/core/handlers/base.py", line 113, in _get_response
    response = wrapped_callback(request, *callback_args, **callback_kwargs)
  File "/root/.virtualenvs/venv/lib/python3.6/site-packages/django/views/generic/base.py", line 71, in view
    return self.dispatch(request, *args, **kwargs)
  File "/root/.virtualenvs/venv/lib/python3.6/site-packages/django/views/generic/base.py", line 97, in dispatch
    return handler(request, *args, **kwargs)
  File "/home/django/trainer/website/investmenttrainer/challenge/views.py", line 15, in get
    challenge = Challenge.objects.get(display_id=self.kwargs.get('pk'))
  File "/root/.virtualenvs/venv/lib/python3.6/site-packages/django/db/models/manager.py", line 82, in manager_method
    return getattr(self.get_queryset(), name)(*args, **kwargs)
  File "/root/.virtualenvs/venv/lib/python3.6/site-packages/django/db/models/query.py", line 417, in get
    self.model._meta.object_name
challenge.models.Challenge.DoesNotExist: Challenge matching query does not exist.
[27/Jan/2020 18:40:47] WARNING [django.request:228] Not Found: /robots.txt
[27/Jan/2020 19:35:25] ERROR [django.request:228] Internal Server Error: /challenge/2222465083798617/
Traceback (most recent call last):
  File "/root/.virtualenvs/venv/lib/python3.6/site-packages/django/core/handlers/exception.py", line 34, in inner
    response = get_response(request)
  File "/root/.virtualenvs/venv/lib/python3.6/site-packages/django/core/handlers/base.py", line 115, in _get_response
    response = self.process_exception_by_middleware(e, request)
  File "/root/.virtualenvs/venv/lib/python3.6/site-packages/django/core/handlers/base.py", line 113, in _get_response
    response = wrapped_callback(request, *callback_args, **callback_kwargs)
  File "/root/.virtualenvs/venv/lib/python3.6/site-packages/django/views/generic/base.py", line 71, in view
    return self.dispatch(request, *args, **kwargs)
  File "/root/.virtualenvs/venv/lib/python3.6/site-packages/django/views/generic/base.py", line 97, in dispatch
    return handler(request, *args, **kwargs)
  File "/home/django/trainer/website/investmenttrainer/challenge/views.py", line 15, in get
    challenge = Challenge.objects.get(display_id=self.kwargs.get('pk'))
  File "/root/.virtualenvs/venv/lib/python3.6/site-packages/django/db/models/manager.py", line 82, in manager_method
    return getattr(self.get_queryset(), name)(*args, **kwargs)
  File "/root/.virtualenvs/venv/lib/python3.6/site-packages/django/db/models/query.py", line 417, in get
    self.model._meta.object_name
challenge.models.Challenge.DoesNotExist: Challenge matching query does not exist.
[27/Jan/2020 19:37:42] ERROR [django.request:228] Internal Server Error: /challenge/9168978265448864/
Traceback (most recent call last):
  File "/root/.virtualenvs/venv/lib/python3.6/site-packages/django/core/handlers/exception.py", line 34, in inner
    response = get_response(request)
  File "/root/.virtualenvs/venv/lib/python3.6/site-packages/django/core/handlers/base.py", line 115, in _get_response
    response = self.process_exception_by_middleware(e, request)
  File "/root/.virtualenvs/venv/lib/python3.6/site-packages/django/core/handlers/base.py", line 113, in _get_response
    response = wrapped_callback(request, *callback_args, **callback_kwargs)
  File "/root/.virtualenvs/venv/lib/python3.6/site-packages/django/views/generic/base.py", line 71, in view
    return self.dispatch(request, *args, **kwargs)
  File "/root/.virtualenvs/venv/lib/python3.6/site-packages/django/views/generic/base.py", line 97, in dispatch
    return handler(request, *args, **kwargs)
  File "/home/django/trainer/website/investmenttrainer/challenge/views.py", line 15, in get
    challenge = Challenge.objects.get(display_id=self.kwargs.get('pk'))
  File "/root/.virtualenvs/venv/lib/python3.6/site-packages/django/db/models/manager.py", line 82, in manager_method
    return getattr(self.get_queryset(), name)(*args, **kwargs)
  File "/root/.virtualenvs/venv/lib/python3.6/site-packages/django/db/models/query.py", line 417, in get
    self.model._meta.object_name
challenge.models.Challenge.DoesNotExist: Challenge matching query does not exist.
[27/Jan/2020 19:40:35] ERROR [django.request:228] Internal Server Error: /challenge/1594981763972756/
Traceback (most recent call last):
  File "/root/.virtualenvs/venv/lib/python3.6/site-packages/django/core/handlers/exception.py", line 34, in inner
    response = get_response(request)
  File "/root/.virtualenvs/venv/lib/python3.6/site-packages/django/core/handlers/base.py", line 115, in _get_response
    response = self.process_exception_by_middleware(e, request)
  File "/root/.virtualenvs/venv/lib/python3.6/site-packages/django/core/handlers/base.py", line 113, in _get_response
    response = wrapped_callback(request, *callback_args, **callback_kwargs)
  File "/root/.virtualenvs/venv/lib/python3.6/site-packages/django/views/generic/base.py", line 71, in view
    return self.dispatch(request, *args, **kwargs)
  File "/root/.virtualenvs/venv/lib/python3.6/site-packages/django/views/generic/base.py", line 97, in dispatch
    return handler(request, *args, **kwargs)
  File "/home/django/trainer/website/investmenttrainer/challenge/views.py", line 15, in get
    challenge = Challenge.objects.get(display_id=self.kwargs.get('pk'))
  File "/root/.virtualenvs/venv/lib/python3.6/site-packages/django/db/models/manager.py", line 82, in manager_method
    return getattr(self.get_queryset(), name)(*args, **kwargs)
  File "/root/.virtualenvs/venv/lib/python3.6/site-packages/django/db/models/query.py", line 417, in get
    self.model._meta.object_name
challenge.models.Challenge.DoesNotExist: Challenge matching query does not exist.
[27/Jan/2020 22:01:21] ERROR [django.request:228] Internal Server Error: /challenge/4388099741860954/
Traceback (most recent call last):
  File "/root/.virtualenvs/venv/lib/python3.6/site-packages/django/core/handlers/exception.py", line 34, in inner
    response = get_response(request)
  File "/root/.virtualenvs/venv/lib/python3.6/site-packages/django/core/handlers/base.py", line 115, in _get_response
    response = self.process_exception_by_middleware(e, request)
  File "/root/.virtualenvs/venv/lib/python3.6/site-packages/django/core/handlers/base.py", line 113, in _get_response
    response = wrapped_callback(request, *callback_args, **callback_kwargs)
  File "/root/.virtualenvs/venv/lib/python3.6/site-packages/django/views/generic/base.py", line 71, in view
    return self.dispatch(request, *args, **kwargs)
  File "/root/.virtualenvs/venv/lib/python3.6/site-packages/django/views/generic/base.py", line 97, in dispatch
    return handler(request, *args, **kwargs)
  File "/home/django/trainer/website/investmenttrainer/challenge/views.py", line 15, in get
    challenge = Challenge.objects.get(display_id=self.kwargs.get('pk'))
  File "/root/.virtualenvs/venv/lib/python3.6/site-packages/django/db/models/manager.py", line 82, in manager_method
    return getattr(self.get_queryset(), name)(*args, **kwargs)
  File "/root/.virtualenvs/venv/lib/python3.6/site-packages/django/db/models/query.py", line 417, in get
    self.model._meta.object_name
challenge.models.Challenge.DoesNotExist: Challenge matching query does not exist.
[28/Jan/2020 00:51:24] ERROR [django.request:228] Internal Server Error: /challenge/6159307766240970/
Traceback (most recent call last):
  File "/root/.virtualenvs/venv/lib/python3.6/site-packages/django/core/handlers/exception.py", line 34, in inner
    response = get_response(request)
  File "/root/.virtualenvs/venv/lib/python3.6/site-packages/django/core/handlers/base.py", line 115, in _get_response
    response = self.process_exception_by_middleware(e, request)
  File "/root/.virtualenvs/venv/lib/python3.6/site-packages/django/core/handlers/base.py", line 113, in _get_response
    response = wrapped_callback(request, *callback_args, **callback_kwargs)
  File "/root/.virtualenvs/venv/lib/python3.6/site-packages/django/views/generic/base.py", line 71, in view
    return self.dispatch(request, *args, **kwargs)
  File "/root/.virtualenvs/venv/lib/python3.6/site-packages/django/views/generic/base.py", line 97, in dispatch
    return handler(request, *args, **kwargs)
  File "/home/django/trainer/website/investmenttrainer/challenge/views.py", line 15, in get
    challenge = Challenge.objects.get(display_id=self.kwargs.get('pk'))
  File "/root/.virtualenvs/venv/lib/python3.6/site-packages/django/db/models/manager.py", line 82, in manager_method
    return getattr(self.get_queryset(), name)(*args, **kwargs)
  File "/root/.virtualenvs/venv/lib/python3.6/site-packages/django/db/models/query.py", line 417, in get
    self.model._meta.object_name
challenge.models.Challenge.DoesNotExist: Challenge matching query does not exist.
[28/Jan/2020 02:58:30] ERROR [django.request:228] Internal Server Error: /challenge/7587613702119196/
Traceback (most recent call last):
  File "/root/.virtualenvs/venv/lib/python3.6/site-packages/django/core/handlers/exception.py", line 34, in inner
    response = get_response(request)
  File "/root/.virtualenvs/venv/lib/python3.6/site-packages/django/core/handlers/base.py", line 115, in _get_response
    response = self.process_exception_by_middleware(e, request)
  File "/root/.virtualenvs/venv/lib/python3.6/site-packages/django/core/handlers/base.py", line 113, in _get_response
    response = wrapped_callback(request, *callback_args, **callback_kwargs)
  File "/root/.virtualenvs/venv/lib/python3.6/site-packages/django/views/generic/base.py", line 71, in view
    return self.dispatch(request, *args, **kwargs)
  File "/root/.virtualenvs/venv/lib/python3.6/site-packages/django/views/generic/base.py", line 97, in dispatch
    return handler(request, *args, **kwargs)
  File "/home/django/trainer/website/investmenttrainer/challenge/views.py", line 15, in get
    challenge = Challenge.objects.get(display_id=self.kwargs.get('pk'))
  File "/root/.virtualenvs/venv/lib/python3.6/site-packages/django/db/models/manager.py", line 82, in manager_method
    return getattr(self.get_queryset(), name)(*args, **kwargs)
  File "/root/.virtualenvs/venv/lib/python3.6/site-packages/django/db/models/query.py", line 417, in get
    self.model._meta.object_name
challenge.models.Challenge.DoesNotExist: Challenge matching query does not exist.
[28/Jan/2020 04:24:51] WARNING [django.request:228] Not Found: /robots.txt
[28/Jan/2020 07:09:00] WARNING [django.request:228] Not Found: /robots.txt
[28/Jan/2020 08:29:48] WARNING [django.request:228] Not Found: /robots.txt
