[27/Jan/2020 19:31:30] ERROR [django.request:228] Internal Server Error: /challenge/9709682386775335/
Traceback (most recent call last):
  File "/root/.virtualenvs/venv/lib/python3.6/site-packages/django/core/handlers/exception.py", line 34, in inner
    response = get_response(request)
  File "/root/.virtualenvs/venv/lib/python3.6/site-packages/django/core/handlers/base.py", line 115, in _get_response
    response = self.process_exception_by_middleware(e, request)
  File "/root/.virtualenvs/venv/lib/python3.6/site-packages/django/core/handlers/base.py", line 113, in _get_response
    response = wrapped_callback(request, *callback_args, **callback_kwargs)
  File "/root/.virtualenvs/venv/lib/python3.6/site-packages/django/views/generic/base.py", line 71, in view
    return self.dispatch(request, *args, **kwargs)
  File "/root/.virtualenvs/venv/lib/python3.6/site-packages/django/views/generic/base.py", line 97, in dispatch
    return handler(request, *args, **kwargs)
  File "/home/django/trainer/website/investmenttrainer/challenge/views.py", line 15, in get
    challenge = Challenge.objects.get(display_id=self.kwargs.get('pk'))
  File "/root/.virtualenvs/venv/lib/python3.6/site-packages/django/db/models/manager.py", line 82, in manager_method
    return getattr(self.get_queryset(), name)(*args, **kwargs)
  File "/root/.virtualenvs/venv/lib/python3.6/site-packages/django/db/models/query.py", line 417, in get
    self.model._meta.object_name
challenge.models.Challenge.DoesNotExist: Challenge matching query does not exist.
[27/Jan/2020 19:43:17] ERROR [django.request:228] Internal Server Error: /challenge/9861560446717568/
Traceback (most recent call last):
  File "/root/.virtualenvs/venv/lib/python3.6/site-packages/django/core/handlers/exception.py", line 34, in inner
    response = get_response(request)
  File "/root/.virtualenvs/venv/lib/python3.6/site-packages/django/core/handlers/base.py", line 115, in _get_response
    response = self.process_exception_by_middleware(e, request)
  File "/root/.virtualenvs/venv/lib/python3.6/site-packages/django/core/handlers/base.py", line 113, in _get_response
    response = wrapped_callback(request, *callback_args, **callback_kwargs)
  File "/root/.virtualenvs/venv/lib/python3.6/site-packages/django/views/generic/base.py", line 71, in view
    return self.dispatch(request, *args, **kwargs)
  File "/root/.virtualenvs/venv/lib/python3.6/site-packages/django/views/generic/base.py", line 97, in dispatch
    return handler(request, *args, **kwargs)
  File "/home/django/trainer/website/investmenttrainer/challenge/views.py", line 15, in get
    challenge = Challenge.objects.get(display_id=self.kwargs.get('pk'))
  File "/root/.virtualenvs/venv/lib/python3.6/site-packages/django/db/models/manager.py", line 82, in manager_method
    return getattr(self.get_queryset(), name)(*args, **kwargs)
  File "/root/.virtualenvs/venv/lib/python3.6/site-packages/django/db/models/query.py", line 417, in get
    self.model._meta.object_name
challenge.models.Challenge.DoesNotExist: Challenge matching query does not exist.
[27/Jan/2020 19:45:44] ERROR [django.request:228] Internal Server Error: /challenge/7351702361068858/
Traceback (most recent call last):
  File "/root/.virtualenvs/venv/lib/python3.6/site-packages/django/core/handlers/exception.py", line 34, in inner
    response = get_response(request)
  File "/root/.virtualenvs/venv/lib/python3.6/site-packages/django/core/handlers/base.py", line 115, in _get_response
    response = self.process_exception_by_middleware(e, request)
  File "/root/.virtualenvs/venv/lib/python3.6/site-packages/django/core/handlers/base.py", line 113, in _get_response
    response = wrapped_callback(request, *callback_args, **callback_kwargs)
  File "/root/.virtualenvs/venv/lib/python3.6/site-packages/django/views/generic/base.py", line 71, in view
    return self.dispatch(request, *args, **kwargs)
  File "/root/.virtualenvs/venv/lib/python3.6/site-packages/django/views/generic/base.py", line 97, in dispatch
    return handler(request, *args, **kwargs)
  File "/home/django/trainer/website/investmenttrainer/challenge/views.py", line 15, in get
    challenge = Challenge.objects.get(display_id=self.kwargs.get('pk'))
  File "/root/.virtualenvs/venv/lib/python3.6/site-packages/django/db/models/manager.py", line 82, in manager_method
    return getattr(self.get_queryset(), name)(*args, **kwargs)
  File "/root/.virtualenvs/venv/lib/python3.6/site-packages/django/db/models/query.py", line 417, in get
    self.model._meta.object_name
challenge.models.Challenge.DoesNotExist: Challenge matching query does not exist.
[27/Jan/2020 20:18:57] ERROR [django.request:228] Internal Server Error: /challenge/1933933792145063/
Traceback (most recent call last):
  File "/root/.virtualenvs/venv/lib/python3.6/site-packages/django/core/handlers/exception.py", line 34, in inner
    response = get_response(request)
  File "/root/.virtualenvs/venv/lib/python3.6/site-packages/django/core/handlers/base.py", line 115, in _get_response
    response = self.process_exception_by_middleware(e, request)
  File "/root/.virtualenvs/venv/lib/python3.6/site-packages/django/core/handlers/base.py", line 113, in _get_response
    response = wrapped_callback(request, *callback_args, **callback_kwargs)
  File "/root/.virtualenvs/venv/lib/python3.6/site-packages/django/views/generic/base.py", line 71, in view
    return self.dispatch(request, *args, **kwargs)
  File "/root/.virtualenvs/venv/lib/python3.6/site-packages/django/views/generic/base.py", line 97, in dispatch
    return handler(request, *args, **kwargs)
  File "/home/django/trainer/website/investmenttrainer/challenge/views.py", line 15, in get
    challenge = Challenge.objects.get(display_id=self.kwargs.get('pk'))
  File "/root/.virtualenvs/venv/lib/python3.6/site-packages/django/db/models/manager.py", line 82, in manager_method
    return getattr(self.get_queryset(), name)(*args, **kwargs)
  File "/root/.virtualenvs/venv/lib/python3.6/site-packages/django/db/models/query.py", line 417, in get
    self.model._meta.object_name
challenge.models.Challenge.DoesNotExist: Challenge matching query does not exist.
[27/Jan/2020 21:57:53] WARNING [django.request:228] Not Found: /Telerik.Web.UI.WebResource.axd
[28/Jan/2020 02:29:37] ERROR [django.request:228] Internal Server Error: /challenge/1650020316512308/
Traceback (most recent call last):
  File "/root/.virtualenvs/venv/lib/python3.6/site-packages/django/core/handlers/exception.py", line 34, in inner
    response = get_response(request)
  File "/root/.virtualenvs/venv/lib/python3.6/site-packages/django/core/handlers/base.py", line 115, in _get_response
    response = self.process_exception_by_middleware(e, request)
  File "/root/.virtualenvs/venv/lib/python3.6/site-packages/django/core/handlers/base.py", line 113, in _get_response
    response = wrapped_callback(request, *callback_args, **callback_kwargs)
  File "/root/.virtualenvs/venv/lib/python3.6/site-packages/django/views/generic/base.py", line 71, in view
    return self.dispatch(request, *args, **kwargs)
  File "/root/.virtualenvs/venv/lib/python3.6/site-packages/django/views/generic/base.py", line 97, in dispatch
    return handler(request, *args, **kwargs)
  File "/home/django/trainer/website/investmenttrainer/challenge/views.py", line 15, in get
    challenge = Challenge.objects.get(display_id=self.kwargs.get('pk'))
  File "/root/.virtualenvs/venv/lib/python3.6/site-packages/django/db/models/manager.py", line 82, in manager_method
    return getattr(self.get_queryset(), name)(*args, **kwargs)
  File "/root/.virtualenvs/venv/lib/python3.6/site-packages/django/db/models/query.py", line 417, in get
    self.model._meta.object_name
challenge.models.Challenge.DoesNotExist: Challenge matching query does not exist.
[28/Jan/2020 05:49:56] ERROR [django.request:228] Internal Server Error: /challenge/5756548206203046/
Traceback (most recent call last):
  File "/root/.virtualenvs/venv/lib/python3.6/site-packages/django/core/handlers/exception.py", line 34, in inner
    response = get_response(request)
  File "/root/.virtualenvs/venv/lib/python3.6/site-packages/django/core/handlers/base.py", line 115, in _get_response
    response = self.process_exception_by_middleware(e, request)
  File "/root/.virtualenvs/venv/lib/python3.6/site-packages/django/core/handlers/base.py", line 113, in _get_response
    response = wrapped_callback(request, *callback_args, **callback_kwargs)
  File "/root/.virtualenvs/venv/lib/python3.6/site-packages/django/views/generic/base.py", line 71, in view
    return self.dispatch(request, *args, **kwargs)
  File "/root/.virtualenvs/venv/lib/python3.6/site-packages/django/views/generic/base.py", line 97, in dispatch
    return handler(request, *args, **kwargs)
  File "/home/django/trainer/website/investmenttrainer/challenge/views.py", line 15, in get
    challenge = Challenge.objects.get(display_id=self.kwargs.get('pk'))
  File "/root/.virtualenvs/venv/lib/python3.6/site-packages/django/db/models/manager.py", line 82, in manager_method
    return getattr(self.get_queryset(), name)(*args, **kwargs)
  File "/root/.virtualenvs/venv/lib/python3.6/site-packages/django/db/models/query.py", line 417, in get
    self.model._meta.object_name
challenge.models.Challenge.DoesNotExist: Challenge matching query does not exist.
[28/Jan/2020 06:47:41] ERROR [django.request:228] Internal Server Error: /challenge/4921591447018249/
Traceback (most recent call last):
  File "/root/.virtualenvs/venv/lib/python3.6/site-packages/django/core/handlers/exception.py", line 34, in inner
    response = get_response(request)
  File "/root/.virtualenvs/venv/lib/python3.6/site-packages/django/core/handlers/base.py", line 115, in _get_response
    response = self.process_exception_by_middleware(e, request)
  File "/root/.virtualenvs/venv/lib/python3.6/site-packages/django/core/handlers/base.py", line 113, in _get_response
    response = wrapped_callback(request, *callback_args, **callback_kwargs)
  File "/root/.virtualenvs/venv/lib/python3.6/site-packages/django/views/generic/base.py", line 71, in view
    return self.dispatch(request, *args, **kwargs)
  File "/root/.virtualenvs/venv/lib/python3.6/site-packages/django/views/generic/base.py", line 97, in dispatch
    return handler(request, *args, **kwargs)
  File "/home/django/trainer/website/investmenttrainer/challenge/views.py", line 15, in get
    challenge = Challenge.objects.get(display_id=self.kwargs.get('pk'))
  File "/root/.virtualenvs/venv/lib/python3.6/site-packages/django/db/models/manager.py", line 82, in manager_method
    return getattr(self.get_queryset(), name)(*args, **kwargs)
  File "/root/.virtualenvs/venv/lib/python3.6/site-packages/django/db/models/query.py", line 417, in get
    self.model._meta.object_name
challenge.models.Challenge.DoesNotExist: Challenge matching query does not exist.
[28/Jan/2020 08:24:54] ERROR [django.request:228] Internal Server Error: /challenge/7153250289599380/
Traceback (most recent call last):
  File "/root/.virtualenvs/venv/lib/python3.6/site-packages/django/core/handlers/exception.py", line 34, in inner
    response = get_response(request)
  File "/root/.virtualenvs/venv/lib/python3.6/site-packages/django/core/handlers/base.py", line 115, in _get_response
    response = self.process_exception_by_middleware(e, request)
  File "/root/.virtualenvs/venv/lib/python3.6/site-packages/django/core/handlers/base.py", line 113, in _get_response
    response = wrapped_callback(request, *callback_args, **callback_kwargs)
  File "/root/.virtualenvs/venv/lib/python3.6/site-packages/django/views/generic/base.py", line 71, in view
    return self.dispatch(request, *args, **kwargs)
  File "/root/.virtualenvs/venv/lib/python3.6/site-packages/django/views/generic/base.py", line 97, in dispatch
    return handler(request, *args, **kwargs)
  File "/home/django/trainer/website/investmenttrainer/challenge/views.py", line 15, in get
    challenge = Challenge.objects.get(display_id=self.kwargs.get('pk'))
  File "/root/.virtualenvs/venv/lib/python3.6/site-packages/django/db/models/manager.py", line 82, in manager_method
    return getattr(self.get_queryset(), name)(*args, **kwargs)
  File "/root/.virtualenvs/venv/lib/python3.6/site-packages/django/db/models/query.py", line 417, in get
    self.model._meta.object_name
challenge.models.Challenge.DoesNotExist: Challenge matching query does not exist.
[28/Jan/2020 09:34:14] ERROR [django.request:228] Internal Server Error: /challenge/8521680866698983/
Traceback (most recent call last):
  File "/root/.virtualenvs/venv/lib/python3.6/site-packages/django/core/handlers/exception.py", line 34, in inner
    response = get_response(request)
  File "/root/.virtualenvs/venv/lib/python3.6/site-packages/django/core/handlers/base.py", line 115, in _get_response
    response = self.process_exception_by_middleware(e, request)
  File "/root/.virtualenvs/venv/lib/python3.6/site-packages/django/core/handlers/base.py", line 113, in _get_response
    response = wrapped_callback(request, *callback_args, **callback_kwargs)
  File "/root/.virtualenvs/venv/lib/python3.6/site-packages/django/views/generic/base.py", line 71, in view
    return self.dispatch(request, *args, **kwargs)
  File "/root/.virtualenvs/venv/lib/python3.6/site-packages/django/views/generic/base.py", line 97, in dispatch
    return handler(request, *args, **kwargs)
  File "/home/django/trainer/website/investmenttrainer/challenge/views.py", line 15, in get
    challenge = Challenge.objects.get(display_id=self.kwargs.get('pk'))
  File "/root/.virtualenvs/venv/lib/python3.6/site-packages/django/db/models/manager.py", line 82, in manager_method
    return getattr(self.get_queryset(), name)(*args, **kwargs)
  File "/root/.virtualenvs/venv/lib/python3.6/site-packages/django/db/models/query.py", line 417, in get
    self.model._meta.object_name
challenge.models.Challenge.DoesNotExist: Challenge matching query does not exist.
[28/Jan/2020 10:09:07] WARNING [django.request:228] Not Found: /robots.txt
[28/Jan/2020 12:01:49] ERROR [django.request:228] Internal Server Error: /challenge/4255483115543122/
Traceback (most recent call last):
  File "/root/.virtualenvs/venv/lib/python3.6/site-packages/django/core/handlers/exception.py", line 34, in inner
    response = get_response(request)
  File "/root/.virtualenvs/venv/lib/python3.6/site-packages/django/core/handlers/base.py", line 115, in _get_response
    response = self.process_exception_by_middleware(e, request)
  File "/root/.virtualenvs/venv/lib/python3.6/site-packages/django/core/handlers/base.py", line 113, in _get_response
    response = wrapped_callback(request, *callback_args, **callback_kwargs)
  File "/root/.virtualenvs/venv/lib/python3.6/site-packages/django/views/generic/base.py", line 71, in view
    return self.dispatch(request, *args, **kwargs)
  File "/root/.virtualenvs/venv/lib/python3.6/site-packages/django/views/generic/base.py", line 97, in dispatch
    return handler(request, *args, **kwargs)
  File "/home/django/trainer/website/investmenttrainer/challenge/views.py", line 15, in get
    challenge = Challenge.objects.get(display_id=self.kwargs.get('pk'))
  File "/root/.virtualenvs/venv/lib/python3.6/site-packages/django/db/models/manager.py", line 82, in manager_method
    return getattr(self.get_queryset(), name)(*args, **kwargs)
  File "/root/.virtualenvs/venv/lib/python3.6/site-packages/django/db/models/query.py", line 417, in get
    self.model._meta.object_name
challenge.models.Challenge.DoesNotExist: Challenge matching query does not exist.
[28/Jan/2020 14:47:09] WARNING [django.request:228] Not Found: /.git/HEAD
