[27/Jan/2020 23:26:41] ERROR [django.request:228] Internal Server Error: /challenge/8545602686228329/
Traceback (most recent call last):
  File "/root/.virtualenvs/venv/lib/python3.6/site-packages/django/core/handlers/exception.py", line 34, in inner
    response = get_response(request)
  File "/root/.virtualenvs/venv/lib/python3.6/site-packages/django/core/handlers/base.py", line 115, in _get_response
    response = self.process_exception_by_middleware(e, request)
  File "/root/.virtualenvs/venv/lib/python3.6/site-packages/django/core/handlers/base.py", line 113, in _get_response
    response = wrapped_callback(request, *callback_args, **callback_kwargs)
  File "/root/.virtualenvs/venv/lib/python3.6/site-packages/django/views/generic/base.py", line 71, in view
    return self.dispatch(request, *args, **kwargs)
  File "/root/.virtualenvs/venv/lib/python3.6/site-packages/django/views/generic/base.py", line 97, in dispatch
    return handler(request, *args, **kwargs)
  File "/home/django/trainer/website/investmenttrainer/challenge/views.py", line 15, in get
    challenge = Challenge.objects.get(display_id=self.kwargs.get('pk'))
  File "/root/.virtualenvs/venv/lib/python3.6/site-packages/django/db/models/manager.py", line 82, in manager_method
    return getattr(self.get_queryset(), name)(*args, **kwargs)
  File "/root/.virtualenvs/venv/lib/python3.6/site-packages/django/db/models/query.py", line 417, in get
    self.model._meta.object_name
challenge.models.Challenge.DoesNotExist: Challenge matching query does not exist.
[28/Jan/2020 04:24:56] ERROR [django.request:228] Internal Server Error: /challenge/1627336981275282/
Traceback (most recent call last):
  File "/root/.virtualenvs/venv/lib/python3.6/site-packages/django/core/handlers/exception.py", line 34, in inner
    response = get_response(request)
  File "/root/.virtualenvs/venv/lib/python3.6/site-packages/django/core/handlers/base.py", line 115, in _get_response
    response = self.process_exception_by_middleware(e, request)
  File "/root/.virtualenvs/venv/lib/python3.6/site-packages/django/core/handlers/base.py", line 113, in _get_response
    response = wrapped_callback(request, *callback_args, **callback_kwargs)
  File "/root/.virtualenvs/venv/lib/python3.6/site-packages/django/views/generic/base.py", line 71, in view
    return self.dispatch(request, *args, **kwargs)
  File "/root/.virtualenvs/venv/lib/python3.6/site-packages/django/views/generic/base.py", line 97, in dispatch
    return handler(request, *args, **kwargs)
  File "/home/django/trainer/website/investmenttrainer/challenge/views.py", line 15, in get
    challenge = Challenge.objects.get(display_id=self.kwargs.get('pk'))
  File "/root/.virtualenvs/venv/lib/python3.6/site-packages/django/db/models/manager.py", line 82, in manager_method
    return getattr(self.get_queryset(), name)(*args, **kwargs)
  File "/root/.virtualenvs/venv/lib/python3.6/site-packages/django/db/models/query.py", line 417, in get
    self.model._meta.object_name
challenge.models.Challenge.DoesNotExist: Challenge matching query does not exist.
[28/Jan/2020 05:40:40] WARNING [django.request:228] Not Found: /robots.txt
[28/Jan/2020 10:33:56] ERROR [django.request:228] Internal Server Error: /challenge/3194238924690287/
Traceback (most recent call last):
  File "/root/.virtualenvs/venv/lib/python3.6/site-packages/django/core/handlers/exception.py", line 34, in inner
    response = get_response(request)
  File "/root/.virtualenvs/venv/lib/python3.6/site-packages/django/core/handlers/base.py", line 115, in _get_response
    response = self.process_exception_by_middleware(e, request)
  File "/root/.virtualenvs/venv/lib/python3.6/site-packages/django/core/handlers/base.py", line 113, in _get_response
    response = wrapped_callback(request, *callback_args, **callback_kwargs)
  File "/root/.virtualenvs/venv/lib/python3.6/site-packages/django/views/generic/base.py", line 71, in view
    return self.dispatch(request, *args, **kwargs)
  File "/root/.virtualenvs/venv/lib/python3.6/site-packages/django/views/generic/base.py", line 97, in dispatch
    return handler(request, *args, **kwargs)
  File "/home/django/trainer/website/investmenttrainer/challenge/views.py", line 15, in get
    challenge = Challenge.objects.get(display_id=self.kwargs.get('pk'))
  File "/root/.virtualenvs/venv/lib/python3.6/site-packages/django/db/models/manager.py", line 82, in manager_method
    return getattr(self.get_queryset(), name)(*args, **kwargs)
  File "/root/.virtualenvs/venv/lib/python3.6/site-packages/django/db/models/query.py", line 417, in get
    self.model._meta.object_name
challenge.models.Challenge.DoesNotExist: Challenge matching query does not exist.
[28/Jan/2020 12:05:34] WARNING [django.request:228] Not Found: /remote/login
[28/Jan/2020 13:54:01] WARNING [django.request:228] Not Found: /index.php
